Workbook
Name Alabama: 'Rate Tables'!$QX$1:$QX$67
Name Arizona: 'Rate Tables'!$QY$1:$QY$15
Name Arkansas: 'Rate Tables'!$QZ$1:$QZ$75
Name Colorado: 'Rate Tables'!$RA$1:$RA$64
Name Connecticut: 'Rate Tables'!$RB$1:$RB$8
Name Delaware: 'Rate Tables'!$RC$1:$RC$3
Name DV_State: 'Rate Tables'!$QW$2:$QW$39
Name Florida: 'Rate Tables'!$RD$1:$RD$71
Name Georgia: 'Rate Tables'!$RE$1:$RE$159
Name HO6_Alabama: 'Rate Tables'!$SK$1:$SK$8
Name HO6_Connecticut: 'Rate Tables'!$SL$1:$SL$8
Name HO6_Delaware: 'Rate Tables'!$SM$1:$SM$2
Name HO6_DV_State: 'Rate Tables'!$SJ$1:$SJ$19
Name HO6_Florida: 'Rate Tables'!$SN$1:$SN$67
Name HO6_Georgia: 'Rate Tables'!$SO$1:$SO$14
Name HO6_Louisiana: 'Rate Tables'!$SP$1:$SP$23
Name HO6_Maine: 'Rate Tables'!$SQ$1:$SQ$15
Name HO6_Maryland: 'Rate Tables'!$SR$1:$SR$5
Name HO6_Massachusetts: 'Rate Tables'!$SS$1:$SS$10
Name HO6_Mississippi: 'Rate Tables'!$ST$1:$ST$6
Name HO6_New_Hampshire: 'Rate Tables'!$SU$1:$SU$6
Name HO6_New_Jersey: 'Rate Tables'!$SV$1:$SV$12
Name HO6_New_York: 'Rate Tables'!$SW$1:$SW$10
Name HO6_North_Carolina: 'Rate Tables'!$SX$1:$SX$26
Name HO6_Rhode_Island: 'Rate Tables'!$SY$1:$SY$5
Name HO6_South_Carolina: 'Rate Tables'!$SZ$1:$SZ$13
Name HO6_Texas: 'Rate Tables'!$TA$1:$TA$27
Name HO6_Virginia: 'Rate Tables'!$TB$1:$TB$14
Name HO6_Washington_DC: 'Rate Tables'!$TC$1:$TC$1
Name Idaho: 'Rate Tables'!$RF$1:$RF$44
Name Illinois: 'Rate Tables'!$RG$1:$RG$102
Name Indiana: 'Rate Tables'!$RH$1:$RH$92
Name Iowa: 'Rate Tables'!$RI$1:$RI$99
Name Kansas: 'Rate Tables'!$RJ$1:$RJ$105
Name Louisiana: 'Rate Tables'!$RK$1:$RK$74
Name Maine: 'Rate Tables'!$RL$1:$RL$16
Name Maryland: 'Rate Tables'!$RM$1:$RM$24
Name Massachusetts: 'Rate Tables'!$RN$1:$RN$14
Name Michigan: 'Rate Tables'!$RO$1:$RO$83
Name Minnesota: 'Rate Tables'!$RP$1:$RP$87
Name Mississippi: 'Rate Tables'!$RQ$1:$RQ$82
Name Missouri: 'Rate Tables'!$RR$1:$RR$115
Name Nevada: 'Rate Tables'!$RS$1:$RS$17
Name New_Hampshire: 'Rate Tables'!$RT$1:$RT$10
Name New_Jersey: 'Rate Tables'!$RU$1:$RU$21
Name New_Mexico: 'Rate Tables'!$RV$1:$RV$33
Name New_York: 'Rate Tables'!$RW$1:$RW$62
Name North_Carolina: 'Rate Tables'!$RX$1:$RX$100
Name Ohio: 'Rate Tables'!$RY$1:$RY$88
Name Oregon: 'Rate Tables'!$RZ$1:$RZ$36
Name Rhode_Island: 'Rate Tables'!$SA$1:$SA$5
Name South_Carolina: 'Rate Tables'!$SB$1:$SB$46
Name Tennessee: 'Rate Tables'!$SC$1:$SC$95
Name Texas: 'Rate Tables'!$SD$1:$SD$254
Name Utah: 'Rate Tables'!$SE$1:$SE$29
Name Virginia: 'Rate Tables'!$SF$1:$SF$140
Name Washington: 'Rate Tables'!$SG$1:$SG$39
Name Washington_DC: 'Rate Tables'!$SH$1:$SH$1
Name Wisconsin: 'Rate Tables'!$SI$1:$SI$72

Sheet Rater
B1: NEW BUSINESS - INPUT VALUES | D1: PARENT ENTITY NAME | E1: ENTITY NAME | F1: ATTRIBUTE NAME | G1: ATTRIBUTE DATA TYPE | H1: ENTITY DATA TYPE | I1: ENTITY TYPE | J1: OPTIONAL/MANDATORY | K1: FALLBACK VALUE | L1: HAS ADDITIONAL CONDITION ADDED (YES/NO) | M1: Apply Prorata | N1: REFERENCE / NOTES | O1: Iterated | P1: Attribute Display Name
A2: =CELL("address",B2) -> $B$2 | B2: Applicable start date | C2: 06/21/2026 | D2: Root | E2: SolartisInsuredV2 | F2: RateLookupDate | G2: Date | H2: Object | I2: Req/Resp | J2: Mandatory | K2: No | L2: No | O2: No | P2: RateLookupDate
A3: =CELL("address",B3) -> $B$3 | B3: Effective date | C3: 46178 | D3: Root | E3: SolartisInsuredV2 | F3: PolicyEffectiveDate | G3: Date | H3: Object | I3: Req/Resp | J3: Mandatory | K3: No | L3: No | O3: No | P3: PolicyEffectiveDate
A4: =CELL("address",B4) -> $B$4 | B4: Expiration date | C4: 46543 | D4: Root | E4: SolartisInsuredV2 | F4: PolicyExpirationDate | G4: Date | H4: Object | I4: Req/Resp | J4: Mandatory | K4: No | L4: No | O4: No | P4: PolicyExpirationDate
A5: =CELL("address",B5) -> $B$5 | B5: Product Data structure | C5: PersonalLines_Property_V2 | D5: Root | E5: SolartisInsuredV2 | F5: ProductName | G5: Varchar | H5: Object | I5: Req/Resp | J5: Mandatory | K5: No | L5: No | O5: No | P5: ProductName
A6: =CELL("address",B6) -> $B$6 | B6: Product Data Structure Version | C6: PersonalLines_Property_V2_Hierarchy_1.0 | D6: Root | E6: SolartisInsuredV2 | F6: ProductVersionNumber | G6: Varchar | H6: Object | I6: Req/Resp | J6: Mandatory | K6: No | L6: No | O6: No | P6: ProductVersionNumber
A7: =CELL("address",B7) -> $B$7 | B7: State Code | C7: =IF(C106="","",LEFT(C106,2)) -> FL | D7: Root | E7: SolartisInsuredV2 | F7: CarrierName | G7: VarChar | H7: Object | I7: Req/Resp | J7: Mandatory | K7: No | L7: No | O7: No | P7: CarrierName
A8: =CELL("address",B8) -> $B$8 | B8: Carrier Name | C8: Lloyds | D8: Root | E8: SolartisInsuredV2 | F8: SublineName | G8: VarChar | H8: Object | I8: Req/Resp | J8: Mandatory | K8: No | L8: No | O8: No | P8: SublineName
A9: =CELL("address",B9) -> $B$9 | B9: Subline Name/Policy Form | C9: HO3 | D9: Root | E9: SolartisInsuredV2 | F9: Company | G9: Map | H9: Object | I9: Req/Resp | J9: Mandatory | K9: No | L9: No | O9: No | P9: Company
A10: =CELL("address",B10) -> $B$10 | B10: Company Short Name | C10: RTPL | D10: Insured | E10: Location | F10: StateRegionCode | G10: VarChar | H10: List | I10: Req/Resp | J10: Mandatory | K10: No | L10: No | O10: No | P10: StateRegionCode
A11: =CELL("address",F11) -> $F$11 | B11: COVERAGE DETAILS | I11: .
A12: =CELL("address",F12) -> $F$12 | B12: Loss Settlement-Dwelling | C12: RCV | D12: Building | E12: Coverage | F12: DwellingValuation | G12: VarChar | H12: List | I12: Req/Resp | J12: Mandatory | K12: No | L12: No | O12: No | P12: DwellingValuation
A13: =CELL("address",F13) -> $F$13 | B13: Loss Settlement-Contents | C13: RCV | D13: Building | E13: Coverage | F13: PersonalPropertyValuation | G13: VarChar | H13: List | I13: Req/Resp | J13: Mandatory | K13: No | L13: No | O13: No | P13: PersonalPropertyValuation
A14: =CELL("address",F14) -> $F$14 | B14: Transaction Type | C14: New_Business | D14: Root | E14: SolartisInsuredV2 | F14: TransactionType | G14: VarChar | H14: Object | I14: Req/Resp | J14: Mandatory | K14: No | L14: No | O14: No | P14: TransactionType
A15: =CELL("address",F15) -> $F$15 | B15: State | C15: Florida | D15: Insured | E15: Location | F15: State | G15: VarChar | H15: List | I15: Req/Resp | J15: Mandatory | K15: No | L15: No | O15: No | P15: State
A16: =CELL("address",F16) -> $F$16 | B16: County | C16: Brevard | D16: Insured | E16: Location | F16: County | G16: VarChar | H16: List | I16: Req/Resp | J16: Mandatory | K16: No | L16: No | O16: No | P16: County
A17: =CELL("address",F17) -> $F$17 | B17: Zip Code | C17: 31404 | D17: Insured | E17: Location | F17: Zipcode1 | G17: VarChar | H17: List | I17: Req/Resp | J17: Mandatory | K17: No | L17: No | O17: No | P17: Zipcode1
A18: =CELL("address",F18) -> $F$18 | B18: Coverage A/Dwelling Coverage | C18: 274000 | D18: Coverage | E18: DwellingCoverage | F18: Limit | G18: Decimal | H18: Map | I18: Req/Resp | J18: Mandatory | K18: 0 | L18: No | O18: No | P18: Limit
A19: =CELL("address",F19) -> $F$19 | B19: Coverage B/Other Structure Coverage | C19: 27400 | D19: Coverage | E19: OtherStructureCoverage | F19: Limit | G19: Decimal | H19: Map | I19: Req/Resp | J19: Mandatory | K19: 0 | L19: No | O19: No | P19: Limit
A20: =CELL("address",F20) -> $F$20 | B20: Coverage C/Personal Property Coverage | C20: 137000 | D20: Coverage | E20: PersonalPropertyCoverage | F20: Limit | G20: Decimal | H20: Map | I20: Req/Resp | J20: Optional | K20: 0 | L20: No | O20: No | P20: Limit
A21: =CELL("address",F21) -> $F$21 | B21: Coverage D/Loss Of Use Coverage | C21: 54800 | D21: Coverage | E21: LossOfUseCoverage | F21: Limit | G21: Decimal | H21: Map | I21: Req/Resp | J21: Mandatory | K21: 0 | L21: No | O21: No | P21: Limit
A22: =CELL("address",F22) -> $F$22 | B22: Distance To Coast | C22: 5 - 10 Mi. | D22: Location | E22: Building | F22: CoastalWaterDistance | G22: Decimal | H22: List | I22: Req/Resp | J22: Mandatory | K22: 0 | L22: No | O22: No | P22: CoastalWaterDistance
A23: =CELL("address",F23) -> $F$23 | B23: Year Built | C23: 2017 | D23: Location | E23: Building | F23: DateBuilt | G23: Int | H23: List | I23: Req/Resp | J23: Mandatory | K23: 0 | L23: No | O23: No | P23: DateBuilt
A24: =CELL("address",F24) -> $F$24 | B24: RISK FACTORS | I24: .
A25: =CELL("address",F25) -> $F$25 | B25: Construction Type | C25: Frame | D25: Location | E25: Building | F25: ConstructionType | G25: VarChar | H25: List | I25: Req/Resp | J25: Mandatory | K25: No | L25: No | O25: No | P25: ConstructionType
A26: =CELL("address",F26) -> $F$26 | B26: Occupancy Type | C26: Primary | D26: Location | E26: Building | F26: Occupancy | G26: VarChar | H26: List | I26: Req/Resp | J26: Mandatory | K26: No | L26: No | O26: No | P26: Occupancy
A27: =CELL("address",F27) -> $F$27 | B27: Age of Dwelling (In Years)/ AgeofHome | C27: 9 | D27: Location | E27: Building | F27: AgeOfHome | G27: Int | H27: List | I27: Req/Resp | J27: Mandatory | K27: 0 | L27: No | O27: No | P27: AgeOfHome
A28: =CELL("address",F28) -> $F$28 | B28: Age of Roof (In Years) | C28: 6 - 10 Years | D28: Location | E28: Building | F28: AgeOfRoof | G28: Int | H28: List | I28: Req/Resp | J28: Mandatory | K28: 0 | L28: No | O28: No | P28: AgeOfRoof
A29: =CELL("address",F29) -> $F$29 | B29: Number Of Stories | C29: 1.5 | D29: Location | E29: Building | F29: NumberOfStories | G29: Decimal | H29: List | I29: Req/Resp | J29: Mandatory | K29: 0 | L29: No | O29: No | P29: NumberOfStories
A30: =CELL("address",F30) -> $F$30 | B30: Number of claims in the past 5 years | C30: 1 | D30: Location | E30: Building | F30: NumberofLosses | G30: Integer | H30: List | I30: Req/Resp | J30: Mandatory | K30: 0 | L30: No | O30: No | P30: NumberOfLosses
A31: =CELL("address",F31) -> $F$31 | B31: Coverage A Band Credit | C31: $250,000 - $349,999 | D31: Location | E31: Building | F31: CoverageABandCredit | G31: Decimal | H31: List | I31: Req/Resp | J31: Mandatory | K31: 0 | L31: No | O31: No | P31: CoverageABandCredit
A32: =CELL("address",F32) -> $F$32 | B32: Extended Replacement Cost | C32: No | D32: Location | E32: Building | F32: ExtendedReplacementCost | G32: VarChar | H32: List | I32: Req/Resp | J32: Mandatory | K32: No | L32: No | O32: No | P32: ExtendedReplacementCost
A33: =CELL("address",F33) -> $F$33 | B33: Number Of Families | C33: 1 | D33: Location | E33: Building | F33: NumberOfFamilies | G33: VarChar | H33: List | I33: Req/Resp | J33: Mandatory | K33: No | L33: No | O33: No | P33: NumberOfFamilies
A34: =CELL("address",F34) -> $F$34 | B34: Protection Class | C34: 2 | D34: Location | E34: Building | F34: ProtectionClass | G34: VarChar | H34: List | I34: Req/Resp | J34: Mandatory | K34: No | L34: No | O34: No | P34: ProtectionClass
A35: =CELL("address",F35) -> $F$35 | B35: Central Station Alarm | C35: None | D35: Location | E35: Building | F35: Alarm | G35: VarChar | H35: List | I35: Req/Resp | J35: Mandatory | K35: No | L35: No | O35: No | P35: Alarm
A36: =CELL("address",F36) -> $F$36 | B36: Water Damage SubLimit | C36: Full Policy Limits | D36: Coverage | E36: WaterDamageSublimit | F36: Limit | G36: Decimal | H36: Map | I36: Req/Resp | J36: Mandatory | K36: 0 | L36: No | O36: No | P36: Limit
A37: =CELL("address",F37) -> $F$37 | B37: AOP Deductible | C37: 1500 | D37: Coverage | E37: AOPDeductible | F37: Limit | G37: Decimal | H37: Map | I37: Req/Resp | J37: Mandatory | K37: 0 | L37: No | O37: No | P37: Limit
A38: =CELL("address",F38) -> $F$38 | B38: Water Damage Deductible | C38: Equal to AOP | D38: Coverage | E38: WaterDamageDeductible | F38: Limit | G38: Decimal | H38: Map | I38: Req/Resp | J38: Mandatory | K38: 0 | L38: No | O38: No | P38: Limit
A39: =CELL("address",F39) -> $F$39 | B39: INSURANCE SCORE | I39: .
A40: =CELL("address",F40) -> $F$40 | B40: Insurance Score Range | C40: 614-652 | D40: Account | E40: Insured | F40: InsuranceScoreRange | G40: String | H40: List | I40: Req/Resp | J40: Mandatory | K40: No | L40: No | O40: No | P40: InsuranceScoreRange
...

Sheet Rate Tables
A1: Table 1 | G1: Table 2 | N1: Table 3 | X1: Table 4 | AD1: Table 5 | AJ1: Table 6 | AQ1: Table 7 | AX1: Table 8 | BF1: Table 9 | BP1: Table 10 | BZ1: Table 11 | CG1: Table 12 | CO1: Table 13 | CS1: Table 14 | CZ1: Table 15 | DG1: Table 16 | DN1: Table 17 | DX1: Table 18 | EF1: Table 19 | EM1: Table 20 | EV1: Table 21 | FF1: Table 22 | FN1: Table 23 | FU1: Table 24 | GB1: Table 25 | GH1: Table 26 | GN1: Table 27 | GT1: Table 28 | HB1: Table 29 | HJ1: Table 30 | HR1: Table 31 | HY1: Table 32 | IF1: Table 33 | IJ1: Table 34 | IQ1: Table 35 | IW1: Table 36 | JC1: Table 37 | JJ1: Table 38 | JS1: Table 39 | JW1: Table 40 | KA1: Table 41 | KE1: Table 42 | KJ1: Table 43 | NG1: Autauga | NI1: Apache | NK1: Arkansas | NM1: Adams | NO1: Fairfield | NQ1: Kent | NS1: Alachua | NU1: Appling | NW1: Ada | NY1: Adams | OA1: Adams | OC1: Adair | OE1: Allen | OG1: Acadia | OI1: Androscoggin | OK1: Allegany | OM1: Barnstable | OO1: Alcona | OQ1: Aitkin | OS1: Adams | OU1: Adair | OW1: Carson City | OY1: Belknap | PA1: Atlantic | PC1: Bernalillo | PE1: Albany | PG1: Alamance | PI1: Adams | PK1: Baker | PM1: Bristol | PO1: Abbeville | PQ1: Anderson | PS1: Anderson | PU1: Beaver | PW1: Alexandria (City) | PY1: Adams | QA1: Adams | QF1: Washington D.C. | QH1: POLICY_FEE_RATE_TABLE State | QI1: State Code | QJ1: Fee 0-999999 | QK1: Fee 1000000+ | QM1: $0 - $99,999 | QR1: DV_Occupancy_Std (non-HO6) | QS1: DV_Occupancy_HO6 | QU1: RTPL_HO6_TCQ_FACTOR (from One London) | QV1: TCQ_FACTOR | QW1: STATE_LIST | QX1: Autauga | QY1: Apache | QZ1: Arkansas | RA1: Adams | RB1: Fairfield | RC1: Kent | RD1: Alachua | RE1: Appling | RF1: Ada | RG1: Adams | RH1: Adams | RI1: Adair | RJ1: Allen | RK1: Acadia | RL1: Androscoggin | RM1: Allegany | RN1: Barnstable | RO1: Alcona | RP1: Aitkin | RQ1: Adams | RR1: Adair | RS1: Carson City | RT1: Belknap | RU1: Atlantic | RV1: Bernalillo | RW1: Albany | RX1: Alamance | RY1: Adams | RZ1: Baker | SA1: Bristol | SB1: Abbeville | SC1: Anderson | SD1: Anderson | SE1: Beaver | SF1: Accomack | SG1: Adams | SH1: Washington D.C. | SI1: Adams | SJ1: Alabama | SK1: BALDWIN | SL1: FAIRFIELD | SM1: KENT | SN1: ALACHUA | SO1: BRANTLEY | SP1: ACADIA | SQ1: ANDROSCOGGIN | SR1: CAROLINE | SS1: BARNSTABLE | ST1: GEORGE | SU1: BELKNAP | SV1: ATLANTIC | SW1: BRONX | SX1: BEAUFORT | SY1: BRISTOL | SZ1: BAMBERG | TA1: ARANSAS | TB1: ACCOMACK | TC1: DISTRICT OF COLUMBIA
A2: Rate Table Name | B2: RTPL_POLICY_FORM_FACTOR | G2: Rate TableName | H2: RTPL_BASE_RATE | N2: Rate Table Name | O2: RTPL_TIV_RATE_RELATIVITY_FACTOR | X2: Rate TableName | Y2: RTPL_MINIMUM_NONWIND_RATE | AD2: Rate TableName | AE2: RTPL_RATINGTERRITORY | AJ2: Rate TableName | AK2: RTPL_CONSTRUCTION_TYPE_FACTOR | AQ2: Rate TableName | AR2: RTPL_OCCUPANCY_FACTOR | AX2: Rate TableName | AY2: RTPL_DWELLING_AGE_FACTOR | BF2: Rate TableName | BG2: RTPL_ROOF_AGE_FACTOR | BP2: Rate TableName | BQ2: RTPL_NUMBER_OF_STORIES_FACTOR | BZ2: Rate TableName | CA2: RTPL_LOSS_SURCHARGE_FACTOR | CG2: Rate TableName | CH2: RTPL_COVEAGE_A_BAND_FACTOR | CO2: Rate TableName | CP2: RTPL_EXTENDED_REPLACEMENT_COST | CS2: Rate TableName | CT2: RTPL_FAMILY_FACTOR | CZ2: Rate TableName | DA2: RTPL_PROTECTION_CLASS_FACTOR | DG2: Rate TableName | DH2: RTPL_CENTRAL_STATION_ALARM_FACTOR | DN2: Rate TableName | DO2: RTPL_WATER_DAMAGE_SUBLIMIT_FACTOR | DX2: Rate TableName | DY2: RTPL_AOP_DEDUCTIBLE_FACTOR | EF2: Rate TableName | EG2: RTPL_WATER_DAMAGE_DEDUCTIBLE_FACTOR | EM2: Rate TableName | EN2: RTPL_INSURANCESCORE_FACTOR | EV2: Rate TableName | EW2: RTPL_AAL_FACTOR | FF2: Rate TableName | FG2: RTPL_MINIMUM_PROPERTY_RATE | FN2: Rate TableName | FO2: RTPL_MOLD_COVERAGE_FACTOR | FU2: Rate TableName | FV2: RTPL_WATERBACKUP_COVERAGE_FACTOR | GB2: Rate TableName | GC2: RTPL_IDENTITYFRAUD_COVERAGE_FACTOR | GH2: Rate TableName | GI2: RTPL_LOSS_ASSESSMENT_COVERAGE_FACTOR | GN2: Rate TableName | GO2: RTPL_PERSONAL_INJURY_LIABILITY_FACTOR | GT2: Rate TableName | GU2: RTPL_EARTHQUAKE_COVERAGE_FACTOR | HB2: Rate TableName | HC2: RTPL_EARTHQUAKE_DEDUCTIBLE_COVERAGE_FACTOR | HJ2: Rate TableName | HK2: RTPL_EARTHQUAKE_COVERAGE_FACTOR_CONDO | HR2: Rate TableName | HS2: RTPL_THEFT_COVERAGEFACTOR | HY2: Rate TableName | HZ2: RTPL_VANDALISM_MISCHIEF_COVERAGE_FACTOR | IF2: Rate TableName | IG2: RTPL_EXTENDED_COVERAGE | IJ2: Rate TableName | IK2: RTPL_LIABILITY_LIMIT_FACTOR | IQ2: Rate TableName | IR2: RTPL_MEDICAL_PAYMENT_FACTOR | IW2: Rate TableName | IX2: RTPL_MINIMUM_PREMIUM_CONDO | JC2: Rate TableName | JD2: RTPL_BOB_ADJUSTMENT_FACTOR | JJ2: Rate TableName | JK2: RTPL_RISK_ADJUSTMENT_FACTOR | JS2: Rate TableName | JT2: RTPL_WIND_HAIL_DEDUCTIBLE_FACTOR_RENEWAL | JW2: Rate TableName | JX2: STATE_AND_COUNTY | KA2: Rate TableName | KB2: RTPL_TERRITORYFACTOR | KE2: Rate TableName | KF2: RSUM_POLICY_FEE_RATE_TABLE | KJ2: Rate Table Name | KK2: RTPL_SCHEDULED_PERSONAL_PROPERTY_COVERAGE_FACTOR | NG2: Barbour | NI2: Coconino | NK2: Baxter | NM2: Arapahoe | NO2: Litchfield | NQ2: New Castle | NS2: Bay | NU2: Atkinson | NW2: Bannock | NY2: Bond | OA2: Bartholomew | OC2: Allamakee | OE2: Atchison | OG2: Allen | OI2: Aroostook | OK2: Anne Arundel | OM2: Berkshire | OO2: Allegan | OQ2: Becker | OS2: Alcorn | OU2: Atchison | OW2: Clark | OY2: Carroll | PA2: Bergen | PC2: Catron | PE2: Allegany | PG2: Alexander | PI2: Ashland | PK2: Clackamas | PM2: Newport | PO2: Aiken | PQ2: Benton | PS2: Andrews | PU2: Cache | PW2: Bristol (City) | PY2: Benton | QA2: Barron | QH2: Alabama | QI2: AL | QJ2: 100 | QK2: 200 | QM2: $100,000 - $149,999 | QN2: HO6 Base Premium (from Reference TIV Rate Relativity H3) | QO2: 500 | QR2: Primary | QS2: Owner - Primary Residence | QU2: AL1 | QV2: 4 | QW2: Alabama | QX2: Baldwin | QY2: Cochise | QZ2: Ashley | RA2: Alamosa | RB2: Hartford | RC2: New Castle | RD2: Baker | RE2: Atkinson | RF2: Adams | RG2: Alexander | RH2: Allen | RI2: Adams | RJ2: Anderson | RK2: Allen | RL2: Aroostook | RM2: Anne Arundel | RN2: Berkshire | RO2: Alger | RP2: Anoka | RQ2: Alcorn | RR2: Andrew | RS2: Churchill | RT2: Carroll | RU2: Bergen | RV2: Catron | RW2: Allegany | RX2: Alexander | RY2: Allen | RZ2: Benton | SA2: Kent | SB2: Aiken | SC2: Bedford | SD2: Andrews | SE2: Box Elder | SF2: Albemarle | SG2: Asotin | SI2: Ashland | SJ2: Connecticut | SK2: CLARKE | SL2: HARTFORD | SM2: SUSSEX | SN2: BAKER | SO2: BRYAN | SP2: ASSUMPTION | SQ2: AROOSTOOK | SR2: DORCHESTER | SS2: BRISTOL | ST2: HANCOCK | SU2: CARROLL | SV2: BURLINGTON | SW2: DUTCHESS | SX2: BERTIE | SY2: KENT | SZ2: BEAUFORT | TA2: BEE | TB2: CHESAPEAKE CITY
A3: Column Name | B3: POLICY_FORM | C3: DWELLING_VALUATION | D3: CONTENT_VALUATION | E3: POLICY_FORM_FACTOR | G3: Column Name | H3: POLICY_FORM | I3: STATE_CODE | J3: TERRITORY | K3: RATING_TERM | L3: RATE | N3: Column Name | O3: POLICY_FORM | P3: STATE_CODE | Q3: DWELLING_MIN | R3: DWELLING_MAX | S3: MINIMUMTIV | T3: TIV_RATE_RELATIVITY_FACTOR | U3: MAXIMUMTIV | V3: MAXTIVRATERELATIVITYFACTOR | X3: Column Name | Y3: POLICY_FORM | Z3: STATE_CODE | AA3: TERRITORY | AB3: RATE | AD3: Column Name | AE3: ZIPCODE | AF3: COUNTY | AG3: STATE | AH3: RATINGTERRITORY | AJ3: Column Name | AK3: POLICY_FORM | AL3: STATE_CODE | AM3: CONSTRUCTION_TYPE | AN3: RATING_TERM | AO3: FACTOR | AQ3: Column Name | AR3: POLICY_FORM | AS3: STATE_CODE | AT3: OCCUPANCY_TYPE | AU3: RATING_TERM | AV3: FACTOR | AX3: Column Name | AY3: POLICY_FORM | AZ3: STATE_CODE | BA3: MINIMUM_DWELLING_AGE | BB3: MAXIMUM_DWELLING_AGE | BC3: RATING_TERM | BD3: DWELLING_AGE_FACTOR | BF3: Column Name | BG3: POLICY_FORM | BH3: STATE_CODE | BI3: MINIMUM_DWELLING_AGE | BJ3: MAXIMUM_DWELLING_AGE | BK3: MINIMUM_ROOF_AGE | BL3: MAXIMUM_ROOF_AGE | BM3: RATING_TERM | BN3: FACTOR | BP3: Column Name | BQ3: POLICY_FORM | BR3: STATE_CODE | BS3: WIND_COVERAGE | BT3: CONSTRUCTION_TYPE | BU3: MINIMUM_STORIES | BV3: MAXIMUM_STORIES | BW3: RATING_TERM | BX3: NUMBER_OF_STORIES_FACTOR | BZ3: Column Name | CA3: POLICY_FORM | CB3: STATE_CODE | CC3: NUMBER_OF_LOSSES | CD3: RATING_TERM | CE3: LOSS_SURCHARGE_FACTOR | CG3: Column Name | CH3: POLICY_FORM | CI3: STATE_CODE | CJ3: DWELLING_COVERAGE_MIN | CK3: DWELLING_COVERAGE_MAX | CL3: RATING_TERM | CM3: COVEAGE_A_BAND_FACTOR | CO3: Column Name | CP3: EXTENDEDREPLACEMENTCOST | CQ3: EXTENDEDREPLACEMENTCOSTFACTOR | CS3: Column Name | CT3: POLICY_FORM | CU3: STATE_CODE | CV3: NUMBER_OF_FAMILIES | CW3: RATING_TERM | CX3: FACTOR | CZ3: Column Name | DA3: POLICY_FORM | DB3: STATE_CODE | DC3: PROTECTION_CLASS | DD3: RATING_TERM | DE3: FACTOR | DG3: Column Name | DH3: POLICY_FORM | DI3: STATE_CODE | DJ3: ALARM | DK3: RATING_TERM | DL3: FACTOR | DN3: Column Name | DO3: POLICY_FORM | DP3: QUOTE_TYPE | DQ3: STATE_CODE | DR3: COUNTY | DS3: ZIPCODE | DT3: WATER_DAMAGE_SUBLIMIT | DU3: RATING_TERM | DV3: FACTOR | DX3: Column Name | DY3: POLICY_FORM | DZ3: STATE_CODE | EA3: AOP_DEDUCTIBLE | EB3: DEDUCTIBLE_TYPE | EC3: RATING_TERM | ED3: FACTOR | EF3: Column Name | EG3: POLICY_FORM | EH3: STATE_CODE | EI3: AOP_DEDUCTIBLE | EJ3: WATER_DAMAGE_DEDUCTIBLE | EK3: FACTOR | EM3: Column Name | EN3: POLICY_FORM | EO3: STATE_CODE | EP3: SCORE_STATUS | EQ3: MIN_SCORE | ER3: MAX_SCORE | ES3: RATING_TERM | ET3: FACTOR | EV3: Column Name | EW3: POLICY_FORM | EX3: STATE_CODE | EY3: TERRITORY | EZ3: MINIMUM_YEAR_BUILT | FA3: MAXIMUM_YEAR_BUILT | FB3: TIGER_CQ_APPLICABLE | FC3: RATING_TERM | FD3: AAL_FACTOR | FF3: Column Name | FG3: POLICY_FORM | FH3: STATE_CODE | FI3: TERRITORY | FJ3: DISTANCE_TO_COASTAL | FK3: RATING_TERM | FL3: FACTOR | FN3: Column Name | FO3: POLICY_FORM | FP3: STATE_CODE | FQ3: MOLD_LIMIT | FR3: RATING_TERM | FS3: FACTOR | FU3: Column Name | FV3: POLICY_FORM | FW3: STATE_CODE | FX3: WATER_BACKUP_LIMIT | FY3: RATING_TERM | FZ3: WATERBACKUP_COVERAGE_FACTOR | GB3: Column Name | GC3: POLICY_FORM | GD3: STATE_CODE | GE3: ID_FRAUD_LIMIT | GF3: FACTOR | GH3: Column Name | GI3: POLICY_FORM | GJ3: STATE_CODE | GK3: LOSS_ASSESSMENT_LIMIT | GL3: LOSS_ASSESSMENT_COVERAGE_FACTOR | GN3: Column Name | GO3: POLICY_FORM | GP3: STATE_CODE | GQ3: PERSONAL_INJURY_LIABILITY | GR3: PERSONAL_INJURY_LIABILITY_FACTOR | GT3: Column Name | GU3: POLICY_FORM | GV3: STATE_CODE | GW3: EARTHQUAKE_SELECTED | GX3: CONSTRUCTION_TYPE | GY3: RATING_TERM | GZ3: EARTHQUAKE_COVERAGE_FACTOR | HB3: Column Name | HC3: POLICY_FORM | HD3: STATE_CODE | HE3: EARTHQUAKE_EXCLUDED | HF3: DEDUCTIBLE_PERCENT | HG3: RATING_TERM | HH3: EARTHQUAKE_DEDUCTIBLE_COVERAGE_FACTOR | HJ3: Column Name | HK3: POLICY_FORM | HL3: STATE_CODE | HM3: EARTHQUAKE_DEDUCTIBLE | HN3: EARTHQUAKE_SELECTED | HO3: CONSTRUCTION_TYPE | HP3: EARTHQUAKE_COVERAGE_FACTOR | HR3: Column Name | HS3: POLICY_FORM | HT3: STATE_CODE | HU3: THEFT_LIMIT | HV3: RATING_TERM | HW3: FACTOR | HY3: Column Name | HZ3: POLICY_FORM | IA3: STATE_CODE | IB3: VANDALISM_COVERAGE | IC3: RATING_TERM | ID3: FACTOR | IF3: Column Name | IG3: EXTENDED_COVERAGE | IH3: FACTOR | IJ3: Column Name | IK3: POLICY_FORM | IL3: STATE_CODE | IM3: LIABILITY_LIMIT | IN3: RATING_TERM | IO3: LIABILITY_LIMIT_FACTOR | IQ3: Column Name | IR3: POLICY_FORM | IS3: STATE_CODE | IT3: MEDICAL_LIMIT | IU3: MEDICAL_PAYMENT_FACTOR | IW3: Column Name | IX3: POLICY_FORM | IY3: STATE_CODE | IZ3: TERRITORY | JA3: MINIMUM_PREMIUM | JC3: Column Name | JD3: STATE | JE3: ZIPCODE | JF3: COUNTY | JG3: CITY | JH3: BOBAPPLICABLEFACTOR | JJ3: Column Name | JK3: STATE | JL3: ZIPCODE | JM3: COUNTY | JN3: CITY | JO3: AGEOFHOMERISKFACTOR | JP3: CONSTRUCTIONTYPERISKFACTOR | JQ3: ROOFAGERISKFACTOR | JS3: Column Name | JT3: WINDDEDUCTIBLE | JU3: WINDHAILDEDUCTIBLEFACTOR | JW3: Column Name | JX3: State | JY3: County | KA3: Column Name | KB3: TERRITORY | KC3: TERRITORYFACTOR | KE3: Column Name | KF3: SUBLINE_NAME | KG3: STATE | KH3: POLICY_FEE | KJ3: Column Name | KK3: POLICY_FORM | KL3: PERSONAL_PROPERTY_TYPE | KM3: SCHEDULED_PERSONAL_PROPERTY_ COVERAGE_FACTOR | NG3: Baldwin | NI3: Cochise | NK3: Ashley | NM3: Alamosa | NO3: Hartford | NQ3: Sussex | NS3: Baker | NU3: Bacon | NW3: Adams | NY3: Alexander | OA3: Allen | OC3: Adams | OE3: Anderson | OG3: Ascension | OI3: Cumberland | OK3: Baltimore | OM3: Bristol | OO3: Alger | OQ3: Anoka | OS3: Amite | OU3: Andrew | OW3: Churchill | OY3: Cheshire | PA3: Burlington | PC3: Chaves | PE3: Bronx | PG3: Alleghany | PI3: Allen | PK3: Benton | PM3: Kent | PO3: Allendale | PQ3: Bedford | PS3: Angelina | PU3: Box Elder | PW3: Buena Vista (City) | PY3: Asotin | QA3: Ashland | QH3: Alaska | QI3: AK | QJ3: 100 | QK3: 200 | QM3: $150,000-$249,999 | QR3: Secondary/Seasonal | QS3: Owner - Secondary Residence | QU3: AL2 | QV3: 4 | QW3: Arizona | QX3: Barbour | QY3: Coconino | QZ3: Baxter | RA3: Arapahoe | RB3: Litchfield | RC3: Sussex | RD3: Bay | RE3: Bacon | RF3: Bannock | RG3: Bond | RH3: Bartholomew | RI3: Allamakee | RJ3: Atchison | RK3: Ascension | RL3: Cumberland | RM3: Baltimore | RN3: Bristol | RO3: Allegan | RP3: Becker | RQ3: Amite | RR3: Atchison | RS3: Clark | RT3: Cheshire | RU3: Burlington | RV3: Chaves | RW3: Bronx | RX3: Alleghany | RY3: Ashland | RZ3: Clackamas | SA3: Newport | SB3: Allendale | SC3: Benton | SD3: Angelina | SE3: Cache | SF3: Alexandria (City) | SG3: Benton | SI3: Barron | SJ3: Delaware | SK3: COVINGTON | SL3: LITCHFIELD | SN3: BAY | SO3: BULLOCH | SP3: CALCASIEU | SQ3: CUMBERLAND | SR3: SOMERSET | SS3: DUKES | ST3: HARRISON | SU3: HILLSBOROUGH | SV3: CAMDEN | SW3: KINGS | SX3: BLADEN | SY3: NEWPORT | SZ3: BERKELEY | TA3: BRAZORIA | TB3: GLOUCESTER
A4: Column Category (Input/Output) | B4: Input | C4: Input | D4: Input | E4: Output | G4: Column Category (Input/Output) | H4: Input | I4: Input | J4: Input | K4: Input | L4: Output | N4: Column Category (Input/Output) | O4: Input | P4: Input | Q4: Input | R4: Input | S4: Output | T4: Output | U4: Output | V4: Output | X4: Column Category (Input/Output) | Y4: Input | Z4: Input | AA4: Input | AB4: Output | AD4: Column Category (Input/Output) | AE4: Input | AF4: Input | AG4: Input | AH4: Output | AJ4: Column Category (Input/Output) | AK4: Input | AL4: Input | AM4: Input | AN4: Input | AO4: Output | AQ4: Column Category (Input/Output) | AR4: Input | AS4: Input | AT4: Input | AU4: Input | AV4: Output | AX4: Column Category (Input/Output) | AY4: Input | AZ4: Input | BA4: Input | BB4: Input | BC4: Input | BD4: Output | BF4: Column Category (Input/Output) | BG4: Input | BH4: Input | BI4: Input | BJ4: Input | BK4: Input | BL4: Input | BM4: Input | BN4: Output | BP4: Column Category (Input/Output) | BQ4: Input | BR4: Input | BS4: Input | BT4: Input | BU4: Input | BV4: Input | BW4: Input | BX4: Output | BZ4: Column Category (Input/Output) | CA4: Input | CB4: Input | CC4: Input | CD4: Input | CE4: Output | CG4: Column Category (Input/Output) | CH4: Input | CI4: Input | CJ4: Input | CK4: Input | CL4: Input | CM4: Output | CO4: Column Category (Input/Output) | CP4: Input | CQ4: Output | CS4: Column Category (Input/Output) | CT4: Input | CU4: Input | CV4: Input | CW4: Input | CX4: Output | CZ4: Column Category (Input/Output) | DA4: Input | DB4: Input | DC4: Input | DD4: Input | DE4: Output | DG4: Column Category (Input/Output) | DH4: Input | DI4: Input | DJ4: Input | DK4: Input | DL4: Output | DN4: Column Category (Input/Output) | DO4: Input | DP4: Input | DQ4: Input | DR4: Input | DS4: Input | DT4: Input | DU4: Input | DV4: Output | DX4: Column Category (Input/Output) | DY4: Input | DZ4: Input | EA4: Input | EB4: Input | EC4: Input | ED4: Output | EF4: Column Category (Input/Output) | EG4: Input | EH4: Input | EI4: Input | EJ4: Input | EK4: Output | EM4: Column Category (Input/Output) | EN4: Input | EO4: Input | EP4: Input | EQ4: Input | ER4: Input | ES4: Input | ET4: Output | EV4: Column Category (Input/Output) | EW4: Input | EX4: Input | EY4: Input | EZ4: Input | FA4: Input | FB4: Input | FC4: Input | FD4: Output | FF4: Column Category (Input/Output) | FG4: Input | FH4: Input | FI4: Input | FJ4: Input | FK4: Input | FL4: Output | FN4: Column Category (Input/Output) | FO4: Input | FP4: Input | FQ4: Input | FR4: Input | FS4: Output | FU4: Column Category (Input/Output) | FV4: Input | FW4: Input | FX4: Input | FY4: Input | FZ4: Output | GB4: Column Category (Input/Output) | GC4: Input | GD4: Input | GE4: Input | GF4: Output | GH4: Column Category (Input/Output) | GI4: Input | GJ4: Input | GK4: Input | GL4: Output | GN4: Column Category (Input/Output) | GO4: Input | GP4: Input | GQ4: Input | GR4: Output | GT4: Column Category (Input/Output) | GU4: Input | GV4: Input | GW4: Input | GX4: Input | GY4: Input | GZ4: Output | HB4: Column Category (Input/Output) | HC4: Input | HD4: Input | HE4: Input | HF4: Input | HG4: Input | HH4: Output | HJ4: Column Category (Input/Output) | HK4: Input | HL4: Input | HM4: Input | HN4: Input | HO4: Input | HP4: Output | HR4: Column Category (Input/Output) | HS4: Input | HT4: Input | HU4: Input | HV4: Input | HW4: Output | HY4: Column Category (Input/Output) | HZ4: Input | IA4: Input | IB4: Input | IC4: Input | ID4: Output | IF4: Column Category (Input/Output) | IG4: Input | IH4: Output | IJ4: Column Category (Input/Output) | IK4: Input | IL4: Input | IM4: Input | IN4: Input | IO4: Output | IQ4: Column Category (Input/Output) | IR4: Input | IS4: Input | IT4: Input | IU4: Output | IW4: Column Category (Input/Output) | IX4: Input | IY4: Input | IZ4: Input | JA4: Output | JC4: Column Category (Input/Output) | JD4: Input | JE4: Input | JF4: Input | JG4: Input | JH4: Output | JJ4: Column Category (Input/Output) | JK4: Input | JL4: Input | JM4: Input | JN4: Input | JO4: Output | JP4: Output | JQ4: Output | JS4: Column Category (Input/Output) | JT4: Input | JU4: Output | JW4: Column Category (Input/Output) | JX4: Input | JY4: Input | KA4: Column Category (Input/Output) | KB4: Input | KC4: Output | KE4: Column Category (Input/Output) | KF4: Input | KG4: Input | KH4: Output | KJ4: Column Category (Input/Output) | KK4: Input | KL4: Input | KM4: Output | NG4: Bibb | NI4: Gila | NK4: Benton | NM4: Archuleta | NO4: Middlesex | NS4: Bradford | NU4: Baker | NW4: Bear Lake | NY4: Boone | OA4: Benton | OC4: Appanoose | OE4: Barber | OG4: Assumption | OI4: Franklin | OK4: Baltimore City | OM4: Dukes | OO4: Alpena | OQ4: Beltrami | OS4: Attala | OU4: Audrain | OW4: Douglas | OY4: Coos | PA4: Camden | PC4: Cibola | PE4: Broome | PG4: Anson | PI4: Ashtabula | PK4: Clatsop | PM4: Providence | PO4: Anderson | PQ4: Bledsoe | PS4: Aransas | PU4: Carbon | PW4: Charlottesville (City) | PY4: Chelan | QA4: Bayfield | QH4: Arizona | QI4: AZ | QJ4: 100 | QK4: 200 | QM4: $250,000 - $349,999 | QR4: Long-Term Rental | QS4: Rental - Annual | QU4: AL3 | QV4: 4 | QW4: Arkansas | QX4: Bibb | QY4: Gila | QZ4: Benton | RA4: Archuleta | RB4: Middlesex | RD4: Bradford | RE4: Baker | RF4: Bear Lake | RG4: Boone | RH4: Benton | RI4: Appanoose | RJ4: Barber | RK4: Assumption | RL4: Franklin | RM4: Baltimore City | RN4: Dukes | RO4: Alpena | RP4: Beltrami | RQ4: Attala | RR4: Audrain | RS4: Douglas | RT4: Coos | RU4: Camden | RV4: Cibola | RW4: Broome | RX4: Anson | RY4: Ashtabula | RZ4: Clatsop | SA4: Providence | SB4: Anderson | SC4: Bledsoe | SD4: Aransas | SE4: Carbon | SF4: Alleghany | SG4: Chelan | SI4: Bayfield | SJ4: Florida | SK4: ESCAMBIA | SL4: MIDDLESEX | SN4: BRADFORD | SO4: CAMDEN | SP4: CAMERON | SQ4: FRANKLIN | SR4: WICOMICO | SS4: ESSEX | ST4: JACKSON | SU4: MERRIMACK | SV4: CAPE MAY | SW4: NASSAU | SX4: BRUNSWICK | SY4: PROVIDENCE | SZ4: CHARLESTON | TA4: BROOKS | TB4: HAMPTON CITY
A5: Operator | B5: Exact Match | C5: Exact Match | D5: Exact Match | E5: Exact Match | G5: Operator | H5: Exact Match | I5: Exact Match | J5: Exact Match | K5: Exact Match | L5: Exact Match | N5: Operator | O5: Exact Match | P5: Exact Match | Q5: Exact Match | R5: Exact Match | S5: Exact Match | T5: Exact Match | U5: Exact Match | V5: Exact Match | X5: Operator | Y5: Exact Match | Z5: Exact Match | AA5: Exact Match | AB5: Exact Match | AD5: Operator | AE5: Exact Match | AF5: Exact Match | AG5: Exact Match | AH5: Exact Match | AJ5: Operator | AK5: Exact Match | AL5: Exact Match | AM5: Exact Match | AN5: Exact Match | AO5: Exact Match | AQ5: Operator | AR5: Exact Match | AS5: Exact Match | AT5: Exact Match | AU5: Exact Match | AV5: Exact Match | AX5: Operator | AY5: Exact Match | AZ5: Exact Match | BA5: Greater than or equal | BB5: Less than or equal | BC5: Exact Match | BD5: Exact Match | BF5: Operator | BG5: Exact Match | BH5: Exact Match | BI5: Greater than or equal | BJ5: Less than or equal | BK5: Greater than or equal | BL5: Less than or equal | BM5: Exact Match | BN5: Exact Match | BP5: Operator | BQ5: Exact Match | BR5: Exact Match | BS5: Exact Match | BT5: Exact Match | BU5: Greater than or equal | BV5: Less than or equal | BW5: Exact Match | BX5: Exact Match | BZ5: Operator | CA5: Exact Match | CB5: Exact Match | CC5: Exact Match | CD5: Exact Match | CE5: Exact Match | CG5: Operator | CH5: Exact Match | CI5: Exact Match | CJ5: Greater than or equal | CK5: Less than or equal | CL5: Exact Match | CM5: Exact Match | CO5: Operator | CP5: Exact Match | CQ5: Exact Match | CS5: Operator | CT5: Exact Match | CU5: Exact Match | CV5: Exact Match | CW5: Exact Match | CX5: Exact Match | CZ5: Operator | DA5: Exact Match | DB5: Exact Match | DC5: Exact Match | DD5: Exact Match | DE5: Exact Match | DG5: Operator | DH5: Exact Match | DI5: Exact Match | DJ5: Exact Match | DK5: Exact Match | DL5: Exact Match | DN5: Operator | DO5: Exact Match | DP5: Exact Match | DQ5: Exact Match | DR5: Exact Match | DS5: Exact Match | DT5: Exact Match | DU5: Exact Match | DV5: Exact Match | DX5: Operator | DY5: Exact Match | DZ5: Exact Match | EA5: Exact Match | EB5: Exact Match | EC5: Exact Match | ED5: Exact Match | EF5: Operator | EG5: Exact Match | EH5: Exact Match | EI5: Exact Match | EJ5: Exact Match | EK5: Exact Match | EM5: Operator | EN5: Exact Match | EO5: Exact Match | EP5: Exact Match | EQ5: Greater than or equal | ER5: Less than or equal | ES5: Exact Match | ET5: Exact Match | EV5: Operator | EW5: Exact Match | EX5: Exact Match | EY5: Exact Match | EZ5: Greater than or equal | FA5: Less than or equal | FB5: Exact Match | FC5: Exact Match | FD5: Exact Match | FF5: Operator | FG5: Exact Match | FH5: Exact Match | FI5: Exact Match | FJ5: Exact Match | FK5: Exact Match | FL5: Exact Match | FN5: Operator | FO5: Exact Match | FP5: Exact Match | FQ5: Exact Match | FR5: Exact Match | FS5: Exact Match | FU5: Operator | FV5: Exact Match | FW5: Exact Match | FX5: Exact Match | FY5: Exact Match | FZ5: Exact Match | GB5: Operator | GC5: Exact Match | GD5: Exact Match | GE5: Exact Match | GF5: Exact Match | GH5: Operator | GI5: Exact Match | GJ5: Exact Match | GK5: Exact Match | GL5: Exact Match | GN5: Operator | GO5: Exact Match | GP5: Exact Match | GQ5: Exact Match | GR5: Exact Match | GT5: Operator | GU5: Exact Match | GV5: Exact Match | GW5: Exact Match | GX5: Exact Match | GY5: Exact Match | GZ5: Exact Match | HB5: Operator | HC5: Exact Match | HD5: Exact Match | HE5: Exact Match | HF5: Exact Match | HG5: Exact Match | HH5: Exact Match | HJ5: Operator | HK5: Exact Match | HL5: Exact Match | HM5: Exact Match | HN5: Exact Match | HO5: Exact Match | HP5: Exact Match | HR5: Operator | HS5: Exact Match | HT5: Exact Match | HU5: Exact Match | HV5: Exact Match | HW5: Exact Match | HY5: Operator | HZ5: Exact Match | IA5: Exact Match | IB5: Exact Match | IC5: Exact Match | ID5: Exact Match | IF5: Operator | IG5: Exact Match | IH5: Exact Match | IJ5: Operator | IK5: Exact Match | IL5: Exact Match | IM5: Exact Match | IN5: Exact Match | IO5: Exact Match | IQ5: Operator | IR5: Exact Match | IS5: Exact Match | IT5: Exact Match | IU5: Exact Match | IW5: Operator | IX5: Exact Match | IY5: Exact Match | IZ5: Exact Match | JA5: Exact Match | JC5: Operator | JD5: Exact Match | JE5: Exact Match | JF5: Exact Match | JG5: Exact Match | JH5: Exact Match | JJ5: Operator | JK5: Exact Match | JL5: Exact Match | JM5: Exact Match | JN5: Exact Match | JO5: Exact Match | JP5: Exact Match | JQ5: Exact Match | JS5: Operator | JT5: Exact Match | JU5: Exact Match | JW5: Operator | JX5: Exact Match | JY5: Exact Match | KA5: Operator | KB5: Exact Match | KC5: Exact Match | KE5: Operator | KF5: Exact Match | KG5: Exact Match | KH5: Exact Match | KJ5: Operator | KK5: Exact Match | KL5: Exact Match | KM5: Exact Match | NG5: Blount | NI5: Graham | NK5: Boone | NM5: Baca | NO5: New Haven | NS5: Brevard | NU5: Baldwin | NW5: Benewah | NY5: Brown | OA5: Blackford | OC5: Audubon | OE5: Barton | OG5: Avoyelles | OI5: Hancock | OK5: Calvert | OM5: Essex | OO5: Antrim | OQ5: Benton | OS5: Benton | OU5: Barry | OW5: Elko | OY5: Grafton | PA5: Cape May | PC5: Colfax | PE5: Cattaraugus | PG5: Ashe | PI5: Athens | PK5: Columbia | PM5: Washington | PO5: Bamberg | PQ5: Blount | PS5: Archer | PU5: Daggett | PW5: Chesapeake (City) | PY5: Clallam | QA5: Brown | QH5: Arkansas | QI5: AR | QJ5: 100 | QK5: 200 | QM5: $350,000 - $499,999 | QN5: HO6_STORIES_MIN (Reference) | QO5: MAX | QP5: FACTOR | QR5: Short-Term Rental | QS5: Rental - Short Term/Seasonal | QU5: AL4 | QV5: 4 | QW5: Colorado | QX5: Blount | QY5: Graham | QZ5: Boone | RA5: Baca | RB5: New Haven | RD5: Brevard | RE5: Baldwin | RF5: Benewah | RG5: Brown | RH5: Blackford | RI5: Audubon | RJ5: Barton | RK5: Avoyelles | RL5: Hancock | RM5: Calvert | RN5: Essex | RO5: Antrim | RP5: Benton | RQ5: Benton | RR5: Barry | RS5: Elko | RT5: Grafton | RU5: Cape May | RV5: Colfax | RW5: Cattaraugus | RX5: Ashe | RY5: Athens | RZ5: Columbia | SA5: Washington | SB5: Bamberg | SC5: Blount | SD5: Archer | SE5: Daggett | SF5: Amelia | SG5: Clallam | SI5: Brown | SJ5: Georgia | SK5: GENEVA | SL5: NEW HAVEN | SN5: BREVARD | SO5: CHARLTON | SP5: IBERIA | SQ5: HANCOCK | SR5: WORCESTER | SS5: MIDDLESEX | ST5: PEARL RIVER | SU5: ROCKINGHAM | SV5: CUMBERLAND | SW5: NEW YORK | SX5: CAMDEN | SY5: WASHINGTON | SZ5: COLLETON | TA5: CALHOUN | TB5: LANCASTER
A6: DS Attribute Name | B6: SublineName | C6: DwellingValuation | D6: PersonalPropertyValuation | E6: PolicyformFactor | G6: DS Attribute Name | H6: SublineName | I6: StateRegionCode | J6: RatingTerritory | L6: BaseRate | N6: DS Attribute Name | O6: SublineName | P6: StateRegionCode | Q6: TIV | R6: TIV | S6: MinimumTiv | T6: TIVRateRelativityFactor | U6: MaximumTiv | V6: MaxTIVRateRelativityFactor | X6: DS Attribute Name | Y6: SublineName | Z6: StateRegionCode | AA6: RatingTerritory | AB6: MinimumNonWindRate | AD6: DS Attribute Name | AE6: Zipcode1 | AF6: County | AG6: State | AH6: RatingTerritory | AJ6: DS Attribute Name | AK6: SublineName | AL6: StateRegionCode | AM6: ConstructionType | AO6: ConstructionTypeFactor | AQ6: DS Attribute Name | AR6: SublineName | AS6: StateRegionCode | AT6: Occupancy | AV6: OccupancyFactor | AX6: DS Attribute Name | AY6: SublineName | AZ6: StateRegionCode | BA6: AgeOfHome | BB6: AgeOfHome | BD6: AllOtherAgeofHomeFactor | BF6: DS Attribute Name | BG6: SublineName | BH6: StateRegionCode | BI6: AgeOfHome | BJ6: AgeOfHome | BK6: AgeOfRoof | BL6: AgeOfRoof | BN6: AgeOfRoofFactor | BP6: DS Attribute Name | BQ6: SublineName | BR6: StateRegionCode | BS6: CoverageSelected | BT6: ConstructionType | BU6: NumberOfStories | BV6: NumberOfStories | BX6: NumberOfStoriesFactor | BZ6: DS Attribute Name | CA6: SublineName | CB6: StateRegionCode | CC6: NumberofLosses | CE6: LossSurchargeFactor | CG6: DS Attribute Name | CH6: SublineName | CI6: StateRegionCode | CJ6: LimitChosen | CK6: LimitChosen | CM6: CoverageABandFactor | CO6: DS Attribute Name | CP6: ExtendedReplacementCost | CQ6: ExtendedReplacementCostFactor | CS6: DS Attribute Name | CT6: SublineName | CU6: StateRegionCode | CV6: NumberOfFamilies | CX6: FamilyFactor | CZ6: DS Attribute Name | DA6: SublineName | DB6: StateRegionCode | DC6: ProtectionClass | DE6: ProtectionFactor | DG6: DS Attribute Name | DH6: SublineName | DI6: StateRegionCode | DJ6: Alarm | DL6: AlarmFactor | DN6: DS Attribute Name | DO6: SublineName | DP6: QuoteType | DQ6: StateRegionCode | DR6: County | DS6: Zipcode1 | DT6: WaterDamageSublimit | DV6: WaterDamageSublimitFactor | DX6: DS Attribute Name | DY6: SublineName | DZ6: StateRegionCode | EA6: DeductibleAmount | EB6: DeductibleType | ED6: DeductibleFactor | EF6: DS Attribute Name | EG6: SublineName | EH6: StateRegionCode | EI6: DeductibleAmount | EJ6: DeductibleAmount | EK6: DeductibleFactor | EM6: DS Attribute Name | EN6: SublineName | EO6: StateRegionCode | EP6: InsuranceScoreStatus | EQ6: InsuranceScore | ER6: InsuranceScore | ET6: NonWindBaseRate | EV6: DS Attribute Name | EW6: SublineName | EX6: StateRegionCode | EY6: RatingTerritory | EZ6: DateBuilt | FA6: DateBuilt | FB6: TigerCQApplicable | FD6: WindAalFactor | FF6: DS Attribute Name | FG6: SublineName | FH6: StateRegionCode | FI6: RatingTerritory | FJ6: CoastalWaterDistance | FL6: MinimumPropertyRateFactor | FN6: DS Attribute Name | FO6: SublineName | FP6: StateRegionCode | FQ6: LimitChosen | FS6: Premium | FU6: DS Attribute Name | FV6: SublineName | FW6: StateRegionCode | FX6: LimitChosen | FZ6: Premium | GB6: DS Attribute Name | GC6: SublineName | GD6: StateRegionCode | GE6: LimitChosen | GF6: Premium | GH6: DS Attribute Name | GI6: SublineName | GJ6: StateRegionCode | GK6: LimitChosen | GL6: Premium | GN6: DS Attribute Name | GO6: SublineName | GP6: StateRegionCode | GQ6: CoverageSelected | GR6: Premium | GT6: DS Attribute Name | GU6: SublineName | GV6: StateRegionCode | GW6: CoverageSelected | GX6: ConstructionType | GZ6: Factor | HB6: DS Attribute Name | HC6: SublineName | HD6: StateRegionCode | HE6: CoverageSelected | HF6: Deductible | HH6: DeductibleFactor | HJ6: DS Attribute Name | HK6: SublineName | HL6: StateRegionCode | HM6: Deductible | HN6: CoverageSelected | HO6: CoverageSelected | HP6: DeductibleFactor | HR6: DS Attribute Name | HS6: SublineName | HT6: StateRegionCode | HU6: LimitChosen | HW6: Premium | HY6: DS Attribute Name | HZ6: SublineName | IA6: StateRegionCode | IB6: CoverageSelected | ID6: Factor | IF6: DS Attribute Name | IG6: CoverageSelected | IH6: Factor | IJ6: DS Attribute Name | IK6: SublineName | IL6: StateRegionCode | IM6: LimitChosen | IO6: Premium | IQ6: DS Attribute Name | IR6: SublineName | IS6: StateRegionCode | IT6: MedicalLimit | IU6: Premium | IW6: DS Attribute Name | IX6: SublineName | IY6: StateRegionCode | IZ6: RatingTerritory | JA6: MinimumPremium | JC6: DS Attribute Name | JD6: State | JE6: Zipcode1 | JF6: County | JG6: City | JH6: BoBApplicableFactor | JJ6: DS Attribute Name | JK6: State | JL6: Zipcode1 | JM6: County | JN6: City | JO6: AgeOfHomeRiskFactor | JP6: ConstructionTypeRiskFactor | JQ6: RoofAgeRiskFactor | JS6: DS Attribute Name | JT6: WindDeductiblePercentage | JU6: WindHailDeductibleFactorRenewal | JW6: DS Attribute Name | JX6: - | JY6: - | KA6: DS Attribute Name | KB6: RatingTerritory | KC6: TerritoryRelativityFactor | KE6: DS Attribute Name | KF6: SublineName | KG6: StateRegionCode | KH6: PolicyFee | KJ6: DS Attribute Name | KK6: SublineName | KL6: PersonalPropertyType | KM6: ScheduledPersonalPropertyFactor | NG6: Bullock | NI6: Greenlee | NK6: Bradley | NM6: Bent | NO6: New London | NS6: Broward | NU6: Banks | NW6: Bingham | NY6: Bureau | OA6: Boone | OC6: Benton | OE6: Bourbon | OG6: Beauregard | OI6: Kennebec | OK6: Caroline | OM6: Franklin | OO6: Arenac | OQ6: Big Stone | OS6: Bolivar | OU6: Barton | OW6: Esmeralda | OY6: Hillsborough | PA6: Cumberland | PC6: Curry | PE6: Cayuga | PG6: Avery | PI6: Auglaize | PK6: Coos | PO6: Barnwell | PQ6: Bradley | PS6: Armstrong | PU6: Davis | PW6: Colonial Heights (City) | PY6: Clark | QA6: Buffalo | QH6: California | QI6: CA | QJ6: 100 | QK6: 200 | QM6: $500,000 - $1,000,000 | QN6: 1 | QO6: 3 | QP6: 1.1 | QR6: Vacant | QS6: Vacant | QU6: AL5 | QV6: 4 | QW6: Connecticut | QX6: Bullock | QY6: Greenlee | QZ6: Bradley | RA6: Bent | RB6: New London | RD6: Broward | RE6: Banks | RF6: Bingham | RG6: Bureau | RH6: Boone | RI6: Benton | RJ6: Bourbon | RK6: Beauregard | RL6: Kennebec | RM6: Caroline | RN6: Franklin | RO6: Arenac | RP6: Big Stone | RQ6: Bolivar | RR6: Barton | RS6: Esmeralda | RT6: Hillsborough | RU6: Cumberland | RV6: Curry | RW6: Cayuga | RX6: Avery | RY6: Auglaize | RZ6: Coos | SB6: Barnwell | SC6: Bradley | SD6: Armstrong | SE6: Davis | SF6: Amherst | SG6: Clark | SI6: Buffalo | SJ6: Louisiana | SK6: MOBILE | SL6: NEW LONDON | SN6: BROWARD | SO6: CHATHAM | SP6: IBERVILLE | SQ6: KENNEBEC | SS6: NANTUCKET | ST6: STONE | SU6: STRAFFORD | SV6: GLOUCESTER | SW6: PUTNAM | SX6: CARTERET | SZ6: DILLON | TA6: CAMERON | TB6: MATHEWS
A7: Fully Qualified DS Attribute Name | B7: Root/SolartisInsuredV1/SublineName | C7: Location/Building/DwellingValuation | D7: Location/Building/PersonalPropertyValuation | E7: Location/Building/PolicyformFactor | G7: Fully Qualified DS Attribute Name | H7: Root/SolartisInsuredV1/SublineName | I7: Insured/Location/StateRegionCode | J7: Insured/Location/RatingTerritory | L7: Location/Building/BaseRate | N7: Fully Qualified DS Attribute Name | O7: Root/SolartisInsuredV1/SublineName | P7: Insured/Location/StateRegionCode | Q7: Location/Building/TIV | R7: Location/Building/TIV | S7: Location/Building/MinimumTiv | T7: Location/Building/TIVRateRelativityFactor | U7: Location/Building/MaximumTiv | V7: Location/Building/MaxTIVRateRelativityFactor | X7: Fully Qualified DS Attribute Name | Y7: Root/SolartisInsuredV1/SublineName | Z7: Insured/Location/StateRegionCode | AA7: Insured/Location/RatingTerritory | AB7: Location/Building/MinimumNonWindRate | AD7: Fully Qualified DS Attribute Name | AE7: Insured/Location/Zipcode1 | AF7: Insured/Location/County | AG7: Root/SolartisInsuredV1/State | AH7: Insured/Location/RatingTerritory | AJ7: Fully Qualified DS Attribute Name | AK7: Root/SolartisInsuredV1/SublineName | AL7: Insured/Location/StateRegionCode | AM7: Location/Building/ConstructionType | AO7: Location/Building/ConstructionTypeFactor | AQ7: Fully Qualified DS Attribute Name | AR7: Root/SolartisInsuredV1/SublineName | AS7: Insured/Location/StateRegionCode | AT7: Location/Building/Occupancy | AV7: Location/Building/OccupancyFactor | AX7: Fully Qualified DS Attribute Name | AY7: Root/SolartisInsuredV1/SublineName | AZ7: Insured/Location/StateRegionCode | BA7: Location/Building/AgeOfHome | BB7: Location/Building/AgeOfHome | BD7: Location/Building/AllOtherAgeofHomeFactor | BF7: Fully Qualified DS Attribute Name | BG7: Root/SolartisInsuredV1/SublineName | BH7: Insured/Location/StateRegionCode | BI7: Location/Building/AgeOfHome | BJ7: Location/Building/AgeOfHome | BK7: Location/Building/AgeOfRoof | BL7: Location/Building/AgeOfRoof | BN7: Location/Building/AgeOfRoofFactor | BP7: Fully Qualified DS Attribute Name | BQ7: Root/SolartisInsuredV1/SublineName | BR7: Insured/Location/StateRegionCode | BS7: Building/PLWindCoverage/CoverageSelected | BT7: Location/Building/ConstructionType | BU7: Location/Building/NumberOfStories | BV7: Location/Building/NumberOfStories | BX7: Location/Building/NumberOfStoriesFactor | BZ7: Fully Qualified DS Attribute Name | CA7: Root/SolartisInsuredV1/SublineName | CB7: Insured/Location/StateRegionCode | CC7: Location/Building/NumberOfLosses | CE7: Location/Building/LossSurchargeFactor | CG7: Fully Qualified DS Attribute Name | CH7: Root/SolartisInsuredV1/SublineName | CI7: Insured/Location/StateRegionCode | CJ7: Building/DwellingCoverage/LimitChosen | CK7: Building/DwellingCoverage/LimitChosen | CM7: Location/Building/CoverageABandFactor | CO7: Fully Qualified DS Attribute Name | CP7: Location/Building/ExtendedReplacementCost | CQ7: Location/Building/ExtendedReplacementCostFactor | CS7: Fully Qualified DS Attribute Name | CT7: Root/SolartisInsuredV1/SublineName | CU7: Insured/Location/StateRegionCode | CV7: Location/Building/NumberOfFamilies | CX7: Location/Building/FamilyFactor | CZ7: Fully Qualified DS Attribute Name | DA7: Root/SolartisInsuredV1/SublineName | DB7: Insured/Location/StateRegionCode | DC7: Location/Building/ProtectionClass | DE7: Location/Building/ProtectionFactor | DG7: Fully Qualified DS Attribute Name | DH7: Root/SolartisInsuredV1/SublineName | DI7: Insured/Location/StateRegionCode | DJ7: Location/Building/Alarm | DL7: Location/Building/AlarmFactor | DN7: Fully Qualified DS Attribute Name | DO7: Root/SolartisInsuredV1/SublineName | DP7: Root/SolartisInsuredV1/QuoteType | DQ7: Insured/Location/StateRegionCode | DR7: Insured/Location/County | DS7: Insured/Location/Zipcode1 | DT7: Location/Building/WaterDamageSublimit | DV7: Location/Building/WaterDamageSublimitFactor | DX7: Fully Qualified DS Attribute Name | DY7: Root/SolartisInsuredV1/SublineName | DZ7: Insured/Location/StateRegionCode | EA7: Building/AllOtherPerils/DeductibleAmount | EB7: Building/AllOtherPerils/DeductibleType | ED7: Building/AllOtherPerils/DeductibleFactor | EF7: Fully Qualified DS Attribute Name | EG7: Root/SolartisInsuredV1/SublineName | EH7: Insured/Location/StateRegionCode | EI7: Building/AllOtherPerils/DeductibleAmount | EJ7: Building/WaterDamage/DeductibleAmount | EK7: Building/WaterDamage/DeductibleFactor | EM7: Fully Qualified DS Attribute Name | EN7: Root/SolartisInsuredV1/SublineName | EO7: Insured/Location/StateRegionCode | EP7: Account/Insured/InsuranceScoreStatus | EQ7: Account/Insured/InsuranceScore | ER7: Account/Insured/InsuranceScore | ET7: Location/Building/NonWindBaseRate | EV7: Fully Qualified DS Attribute Name | EW7: Root/SolartisInsuredV1/SublineName | EX7: Insured/Location/StateRegionCode | EY7: Insured/Location/RatingTerritory | EZ7: Location/Building/DateBuilt | FA7: Location/Building/DateBuilt | FB7: Location/Building/TigerCQApplicable | FD7: Location/Building/WindAalFactor | FF7: Fully Qualified DS Attribute Name | FG7: Root/SolartisInsuredV1/SublineName | FH7: Insured/Location/StateRegionCode | FI7: Insured/Location/RatingTerritory | FJ7: Location/Building/CoastalWaterDistance | FL7: Location/Building/MinimumPropertyRateFactor | FN7: Fully Qualified DS Attribute Name | FO7: Root/SolartisInsuredV1/SublineName | FP7: Insured/Location/StateRegionCode | FQ7: Building/MoldCoverage/LimitChosen | FS7: Building/MoldCoverage/Premium | FU7: Fully Qualified DS Attribute Name | FV7: Root/SolartisInsuredV1/SublineName | FW7: Insured/Location/StateRegionCode | FX7: Building/WaterBackup/LimitChosen | FZ7: Building/WaterBackup/Premium | GB7: Fully Qualified DS Attribute Name | GC7: Root/SolartisInsuredV1/SublineName | GD7: Insured/Location/StateRegionCode | GE7: Building/IFCoverage/LimitChosen | GF7: Building/IFCoverage/Premium | GH7: Fully Qualified DS Attribute Name | GI7: Root/SolartisInsuredV1/SublineName | GJ7: Insured/Location/StateRegionCode | GK7: Building/LossAssessment/LimitChosen | GL7: Building/LossAssessment/Premium | GN7: Fully Qualified DS Attribute Name | GO7: Root/SolartisInsuredV1/SublineName | GP7: Insured/Location/StateRegionCode | GQ7: Building/PersonalInjuryCoverage/CoverageSelected | GR7: Building/PersonalInjuryCoverage/Premium | GT7: Fully Qualified DS Attribute Name | GU7: Root/SolartisInsuredV1/SublineName | GV7: Insured/Location/StateRegionCode | GW7: Building/EQCoverage/CoverageSelected | GX7: Location/Building/ConstructionType | GZ7: Building/EQCoverage/Factor | HB7: Fully Qualified DS Attribute Name | HC7: Root/SolartisInsuredV1/SublineName | HD7: Insured/Location/StateRegionCode | HE7: Building/EQCoverage/CoverageSelected | HF7: Building/EQCoverage/Deductible | HH7: Building/EQCoverage/DeductibleFactor | HJ7: Fully Qualified DS Attribute Name | HK7: Root/SolartisInsuredV1/SublineName | HL7: Insured/Location/StateRegionCode | HM7: Building/EQCoverage/Deductible | HN7: Building/EQCoverage/CoverageSelected | HO7: Building/EQCoverage/CoverageSelected | HP7: Building/EQCoverage/DeductibleFactor | HR7: Fully Qualified DS Attribute Name | HS7: Root/SolartisInsuredV1/SublineName | HT7: Insured/Location/StateRegionCode | HU7: Building/TheftCoverage/LimitChosen | HW7: Building/TheftCoverage/Premium | HY7: Fully Qualified DS Attribute Name | HZ7: Root/SolartisInsuredV1/SublineName | IA7: Insured/Location/StateRegionCode | IB7: Building/VandalismOrMaliciousMischiefCoverage/CoverageSelected | ID7: Building/VandalismOrMaliciousMischiefCoverage/Factor | IF7: Fully Qualified DS Attribute Name | IG7: Building/ExtendedCoverage/CoverageSelected | IH7: Building/ExtendedCoverage/Factor | IJ7: Fully Qualified DS Attribute Name | IK7: Root/SolartisInsuredV1/SublineName | IL7: Insured/Location/StateRegionCode | IM7: Building/PersonalLiabilityCoverage/LimitChosen | IO7: Building/PersonalLiabilityCoverage/Premium | IQ7: Fully Qualified DS Attribute Name | IR7: Root/SolartisInsuredV1/SublineName | IS7: Insured/Location/StateRegionCode | IT7: Building/MedicalPaymentsCoverage/MedicalLimit | IU7: Building/MedicalPaymentsCoverage/Premium | IW7: Fully Qualified DS Attribute Name | IX7: Root/SolartisInsuredV1/SublineName | IY7: Insured/Location/StateRegionCode | IZ7: Insured/Location/RatingTerritory | JA7: Root/SolartisInsuredV1/MinimumPremium | JC7: Fully Qualified DS Attribute Name | JD7: Root/SolartisInsuredV1/State | JE7: Insured/Location/Zipcode1 | JF7: Insured/Location/County | JG7: Insured/Location/City | JH7: Insured/Location/BoBApplicableFactor | JJ7: Fully Qualified DS Attribute Name | JK7: Root/SolartisInsuredV1/State | JL7: Insured/Location/Zipcode1 | JM7: Insured/Location/County | JN7: Insured/Location/City | JO7: Location/Building/AgeOfHomeRiskFactor | JP7: Location/Building/ConstructionTypeRiskFactor | JQ7: Location/Building/RoofAgeRiskFactor | JS7: Fully Qualified DS Attribute Name | JT7: Location/Building/WindDeductiblePercentage | JU7: Building/Coverage/WindHailDeductibleFactorRenewal | JW7: Fully Qualified DS Attribute Name | JX7: - | JY7: - | KA7: Fully Qualified DS Attribute Name | KB7: Insured/Location/RatingTerritory | KC7: Location/Building/TerritoryRelativityFactor | KE7: Fully Qualified DS Attribute Name | KF7: Root/SolartisInsuredV1/SublineName | KG7: Insured/Location/StateRegionCode | KH7: Root/SolartisInsuredV1/PolicyFee | KJ7: Fully Qualified DS Attribute Name | KK7: Root/SolartisInsuredV1/SublineName | KL7: Location/Building/PersonalPropertyType | KM7: Location/Building/ScheduledPersonalPropertyFactor | NG7: Butler | NI7: La Paz | NK7: Calhoun | NM7: Boulder | NO7: Tolland | NS7: Calhoun | NU7: Barrow | NW7: Blaine | NY7: Calhoun | OA7: Brown | OC7: Black Hawk | OE7: Brown | OG7: Bienville | OI7: Knox | OK7: Carroll | OM7: Hampden | OO7: Baraga | OQ7: Blue Earth | OS7: Calhoun | OU7: Bates | OW7: Eureka | OY7: Merrimack | PA7: Essex | PC7: De Baca | PE7: Chautauqua | PG7: Beaufort | PI7: Belmont | PK7: Crook | PO7: Beaufort | PQ7: Campbell | PS7: Atascosa | PU7: Duchesne | PW7: Covington (City) | PY7: Columbia | QA7: Burnett | QH7: Colorado | QI7: CO | QJ7: 100 | QK7: 200 | QM7: $1,000,000+ | QN7: 4 | QO7: 7 | QP7: 1 | QR7: Builders Risk | QU7: AL6 | QV7: 4 | QW7: Delaware | QX7: Butler | QY7: La Paz | QZ7: Calhoun | RA7: Boulder | RB7: Tolland | RD7: Calhoun | RE7: Barrow | RF7: Blaine | RG7: Calhoun | RH7: Brown | RI7: Black Hawk | RJ7: Brown | RK7: Bienville | RL7: Knox | RM7: Carroll | RN7: Hampden | RO7: Baraga | RP7: Blue Earth | RQ7: Calhoun | RR7: Bates | RS7: Eureka | RT7: Merrimack | RU7: Essex | RV7: De Baca | RW7: Chautauqua | RX7: Beaufort | RY7: Belmont | RZ7: Crook | SB7: Beaufort | SC7: Campbell | SD7: Atascosa | SE7: Duchesne | SF7: Appomattox | SG7: Columbia | SI7: Burnett | SJ7: Maine | SK7: MONROE | SL7: TOLLAND | SN7: CALHOUN | SO7: EFFINGHAM | SP7: JEFFERSON | SQ7: KNOX | SS7: NORFOLK | SV7: HUDSON | SW7: QUEENS | SX7: CHOWAN | SZ7: DORCHESTER | TA7: CHAMBERS | TB7: MIDDLESEX
A8: 1 | B8: DP1 | C8: Actual Cash Value | D8: Actual Cash Value | E8: 0.9 | G8: 1 | H8: HO3 | I8: AK | J8: AK1 | K8: Annual | L8: 0.3675 | N8: 1 | O8: HO6 | P8: CW | Q8: 0 | R8: 4999 | S8: 0 | T8: 0.955 | U8: 5000 | V8: 0.955 | X8: 1 | Y8: HO6 | Z8: CT | AA8: 1 | AB8: 0.2 | AD8: 1 | AE8: 28428 | AF8: New Hanover | AG8: North Carolina | AH8: NC6 | AJ8: 1 | AK8: HO3 | AL8: CW | AM8: Frame | AN8: Annual | AO8: 1 | AQ8: 1 | AR8: HO3 | AS8: CW | AT8: Builders Risk | AU8: Annual | AV8: 1 | AX8: 1 | AY8: HO6 | AZ8: CW | BA8: 0 | BB8: 0 | BC8: Annual | BD8: 0.8 | BF8: 1 | BG8: HO3 | BH8: CW | BI8: -1 | BJ8: 10 | BK8: -1 | BL8: 10 | BM8: Annual | BN8: 1 | BP8: 1 | BQ8: HO6 | BR8: CW | BS8: NO | BT8: Frame | BU8: 0 | BV8: 1 | BW8: Annual | BX8: 1 | BZ8: 1 | CA8: HO3 | CB8: CW | CC8: 0 | CD8: Annual | CE8: 0.98 | CG8: 1 | CH8: Builders Risk | CI8: CW | CJ8: 0 | CK8: 99999 | CL8: Monthly | CM8: 2 | CO8: 1 | CP8: Yes | CQ8: 1.1 | CS8: 1 | CT8: HO3 | CU8: CW | CV8: 1 | CW8: Annual | CX8: 1 | CZ8: 1 | DA8: HO3 | DB8: CW | DC8: 1 | DD8: Annual | DE8: 1 | DG8: 1 | DH8: HO3 | DI8: CW | DJ8: None | DK8: Annual | DL8: 1 | DN8: 1 | DO8: HO3 | DP8: NEW_BUSINESS | DQ8: FL | DR8: ALL | DS8: 33002 | DT8: 10000 | DU8: Annual | DV8: 1 | DX8: 1 | DY8: HO3 | DZ8: CW | EA8: 1000 | EC8: Annual | ED8: 1 | EF8: 1 | EG8: HO6 | EH8: CW | EI8: 500 | EJ8: 10000 | EK8: 0.95 | EM8: 1 | EN8: HO3 | EO8: CW | EP8: 1 | EQ8: 835 | ER8: 997 | ES8: Annual | ET8: 0.75 | EV8: 1 | EW8: HO3 | EX8: AK | EY8: 1 | EZ8: 0 | FA8: 1994 | FB8: N | FC8: Annual | FD8: 0 | FF8: 1 | FG8: HO3 | FH8: AK | FI8: 1 | FJ8: 0 | FK8: Annual | FL8: 0.3 | FN8: 1 | FO8: HO3 | FP8: CW | FQ8: 5000 | FR8: Annual | FS8: 0 | FU8: 1 | FV8: HO3 | FW8: CW | FX8: 0 | FY8: Annual | FZ8: 0 | GB8: 1 | GC8: HO3 | GD8: CW | GE8: 15000 | GF8: 25 | GH8: 1 | GI8: HO6 | GJ8: CW | GK8: 10000 | GL8: 25 | GN8: 1 | GO8: HO6 | GP8: CW | GQ8: No | GR8: 0 | GT8: 1 | GU8: HO3 | GV8: SC | GW8: Yes | GX8: Frame | GY8: Annual | GZ8: 0.1 | HB8: 1 | HC8: HO3 | HD8: SC | HE8: Yes | HF8: 0 | HG8: Annual | HH8: 0 | HJ8: 1 | HK8: HO6 | HL8: SC | HM8: 0 | HN8: Yes | HO8: Fire Resistive | HP8: 0 | HR8: 1 | HS8: HO3 | HT8: CW | HU8: 0 | HV8: Annual | HW8: 0 | HY8: 1 | HZ8: HO3 | IA8: CW | IB8: No | IC8: Annual | ID8: 1 | IF8: 1 | IG8: Included | IH8: 1 | IJ8: 1 | IK8: HO3 | IL8: CW | IM8: 0 | IN8: Annual | IO8: 0 | IQ8: 1 | IR8: HO3 | IS8: CW | IT8: 0 | IU8: 0 | IW8: 1 | IX8: HO6 | IY8: CT | IZ8: 1 | JA8: 350 | JC8: 1 | JD8: Alabama | JE8: ALL | JF8: ALL | JG8: ALL | JH8: -0.05 | JJ8: 1 | JK8: Alabama | JL8: ALL | JM8: ALL | JN8: ALL | JO8: 0.04 | JP8: -0.025 | JQ8: 0.1 | JS8: 1 | JT8: 1000 | JU8: 1 | JW8: 1 | JX8: Alabama | JY8: Autauga | KA8: 1 | KB8: AL8 | KC8: 0.8 | KE8: 1 | KF8: ALL | KG8: MI | KH8: 59 | KJ8: 1 | KK8: HO3 | KL8: Mens Jewelry | KM8: 0.0275 | NG8: Calhoun | NI8: Maricopa | NK8: Carroll | NM8: City & of Broomfield | NO8: Windham | NS8: Charlotte | NU8: Bartow | NW8: Boise | NY8: Carroll | OA8: Carroll | OC8: Boone | OE8: Butler | OG8: Bossier | OI8: Lincoln | OK8: Cecil | OM8: Hampshire | OO8: Barry | OQ8: Brown | OS8: Carroll | OU8: Benton | OW8: Humboldt | OY8: Rockingham | PA8: Gloucester | PC8: Dona Ana | PE8: Chemung | PG8: Bertie | PI8: Brown | PK8: Curry | PO8: Berkeley | PQ8: Cannon | PS8: Austin | PU8: Emery | PW8: Danville (City) | PY8: Cowlitz | QA8: Calumet | QH8: Connecticut | QI8: CT | QJ8: 0 | QK8: 0 | QN8: 8 | QO8: 10 | QP8: 0.95 | QU8: AL7 | QV8: 4 | QW8: Florida | QX8: Calhoun | QY8: Maricopa | QZ8: Carroll | RA8: Chaffee | RB8: Windham | RD8: Charlotte | RE8: Bartow | RF8: Boise | RG8: Carroll | RH8: Carroll | RI8: Boone | RJ8: Butler | RK8: Bossier | RL8: Lincoln | RM8: Cecil | RN8: Hampshire | RO8: Barry | RP8: Brown | RQ8: Carroll | RR8: Benton | RS8: Humboldt | RT8: Rockingham | RU8: Gloucester | RV8: Dona Ana | RW8: Chemung | RX8: Bertie | RY8: Brown | RZ8: Curry | SB8: Berkeley | SC8: Cannon | SD8: Austin | SE8: Emery | SF8: Arlington | SG8: Cowlitz | SI8: Calumet | SJ8: Maryland | SK8: WASHINGTON | SL8: WINDHAM | SN8: CHARLOTTE | SO8: EVANS | SP8: JEFFERSON DAVIS | SQ8: LINCOLN | SS8: PLYMOUTH | SV8: MERCER | SW8: RICHMOND | SX8: COLUMBUS | SZ8: GEORGETOWN | TA8: FORT BEND | TB8: NORFOLK CITY
